Workbook

Sheet Delivery Plan
A1: Item Code Studio — Delivery Plan
A2: Prepared for Anuraag · 6 August 2026 · v2.0 · R1-R5 are today's build runs. S0 = already built and verified. NEEDS INPUT = cannot be done by me; the Notes column says what is required.
A4: ID | B4: Agent | C4: Epic | D4: Story | E4: Acceptance criteria | F4: Priority | G4: Points | H4: Run | I4: Status | J4: Depends on | K4: Notes | L4: Actual Status (this session) | M4: Time Taken | N4: What Worked | O4: Challenges & Deviations from Plan | P4: Built By | Q4: Actual Status (this session) | R4: Time Taken | S4: What Worked | T4: Challenges & Deviations from Plan | U4: Built By
A5: Z1 | B5: 0 Foundation | C5: E0 Brand & Shell | D5: Schema migration | E5: app_user, session, item_version, item_vacancy, llm_cache and sync_log created idempotently. Seeded data survives; counts unchanged after rebuild. | F5: Must | G5: 8 | H5: R1 | I5: Not started | K5: Agent 0 only - nobody else touches db.py | L5: Built & verified | M5: ~45 min, single continuous session, no interruptions | N5: All six tables (app_user, session, item_version, item_vacancy, llm_cache, sync_log) landed as CREATE TABLE IF NOT EXISTS, confirmed empty post-migration. seed.py --rebuild re-run five times to prove non-destructiveness. | O5: Discovered seed.py itself is non-deterministic run-to-run on group/item counts (889/891 groups, 1947/1949 items) across identical reruns - pre-existing, not caused by this migration, but flagged loudly since it could be mistaken for data loss. Mediation: documented plainly in the handover for whoever owns core/matcher.py's dedup path rather than silently noting it. | P5: 0 Foundation | Q5: Built & verified | R5: ~45 min, single continuous session, no interruptions | S5: All six tables (app_user, session, item_version, item_vacancy, llm_cache, sync_log) landed as CREATE TABLE IF NOT EXISTS, confirmed empty post-migration. seed.py --rebuild re-run five times to prove non-destructiveness. | T5: Discovered seed.py itself is non-deterministic run-to-run on group/item counts (889/891 groups, 1947/1949 items) across identical reruns - pre-existing, not caused by this migration, but flagged loudly since it could be mistaken for data loss. Mediation: documented plainly in the handover for whoever owns core/matcher.py's dedup path rather than silently noting it. | U5: 0 Foundation
A6: Z2 | B6: 0 Foundation | C6: E2 API v1 | D6: Split server.py into route modules | E6: routes/ with public, auth, create, master, erp, meta. server.py becomes a thin dispatcher under 120 lines with the two response envelopes. | F6: Must | G6: 8 | H6: R1 | I6: Not started | K6: Stops 8 agents colliding in one file | L6: Built & verified | M6: ~45 min, single continuous session, no interruptions | N6: server.py cut from 515 lines to 91 by extracting HTTP plumbing into a new core/dispatch.py (router, multipart parsing, the request/response cycle) and envelopes into core/api.py - both new files, not anticipated by the original plan, but judged necessary to hit the sub-120-line target cleanly. | O6: The brief said 'under ~120 lines'; a first draft with everything inline came to ~265. Mediation: factored HTTP mechanics out into core/dispatch.py (plumbing, not a route) rather than accept a bloated dispatcher - got to 91 lines. Also had to decide, unprompted by CONTRACTS.md, which module owns ambiguous routes like /api/group/move* - documented every judgement call explicitly in the handover so A and F could override them. | P6: 0 Foundation | Q6: Built & verified | R6: ~45 min, single continuous session, no interruptions | S6: server.py cut from 515 lines to 91 by extracting HTTP plumbing into a new core/dispatch.py (router, multipart parsing, the request/response cycle) and envelopes into core/api.py - both new files, not anticipated by the original plan, but judged necessary to hit the sub-120-line target cleanly. | T6: The brief said 'under ~120 lines'; a first draft with everything inline came to ~265. Mediation: factored HTTP mechanics out into core/dispatch.py (plumbing, not a route) rather than accept a bloated dispatcher - got to 91 lines. Also had to decide, unprompted by CONTRACTS.md, which module owns ambiguous routes like /api/group/move* - documented every judgement call explicitly in the handover so A and F could override them. | U6: 0 Foundation
A7: Z3 | B7: 0 Foundation | C7: E0 Brand & Shell | D7: Settings store and ledger config | E7: db.get_setting / set_setting; config gains ledger.mode host|client. Secrets live in settings, never config.json. | F7: Must | G7: 3 | H7: R1 | I7: Not started | J7: Z1 | L7: Built & verified | M7: ~45 min, single continuous session, no interruptions | N7: ledger config block added exactly as specified, defaulted to local_server since no VPS exists yet. | O7: None of note - this was the most straightforward story in the packet. | P7: 0 Foundation | Q7: Built & verified | R7: ~45 min, single continuous session, no interruptions | S7: ledger config block added exactly as specified, defaulted to local_server since no VPS exists yet. | T7: None of note - this was the most straightforward story in the packet. | U7: 0 Foundation
A8: Z4 | B8: 0 Foundation | C8: E0 Brand & Shell | D8: Theme file and logo asset | E8: web/theme.css with the MiniMines palette as variables, light variant, Barlow. minimines-logo.svg copied from ATT_Platform. | F8: Must | G8: 2 | H8: R1 | I8: Not started | K8: Agent A builds on these variables | L8: Built & verified | M8: ~45 min, single continuous session, no interruptions | N8: web/theme.css created as pure CSS variables (no rules, so it can't visually break anything on its own) and linked into index.html ahead of style.css; logo copied verbatim from ATT_Platform. | O8: None. Deliberately did not restyle any existing page, per the brief. | P8: 0 Foundation | Q8: Built & verified | R8: ~45 min, single continuous session, no interruptions | S8: web/theme.css created as pure CSS variables (no rules, so it can't visually break anything on its own) and linked into index.html ahead of style.css; logo copied verbatim from ATT_Platform. | T8: None. Deliberately did not restyle any existing page, per the brief. | U8: 0 Foundation
A9: K1 | B9: 0 Foundation | C9: E0 Brand & Shell | D9: Apply the MiniMines theme | E9: Palette from m-mines.com (#001b2e navy, #04aed1 teal, #3b6e93 steel), Barlow typeface, minimines-logo.svg in the header. Light and dark both legible. | F9: Must | G9: 5 | H9: R1 | I9: Not started | K9: Reused from ATT_Platform, not reinvented | L9: Built & verified | M9: ~45 min, single continuous session, no interruptions | N9: Same palette/typeface work as Z4 - this row and Z4 describe the same deliverable from two different planning passes. | O9: None beyond what's noted under Z4. | P9: 0 Foundation | Q9: Built & verified | R9: ~45 min, single continuous session, no interruptions | S9: Same palette/typeface work as Z4 - this row and Z4 describe the same deliverable from two different planning passes. | T9: None beyond what's noted under Z4. | U9: 0 Foundation
A10: K2 | B10: A Public | C10: E0 Brand & Shell | D10: Remove the stats block | E10: The counts panel in the bottom-left corner is gone. Nothing shifts or leaves a gap. | F10: Must | G10: 1 | H10: R1 | I10: Not started | J10: K1 | K10: Your instruction | L10: Built & verified | M10: Two segments totalling ~62 tool calls (162,610 tokens) across an initial 600s stall and one transient API disconnect, both recovered. | N10: The three .stat divs and their population code removed from index.html/app.js; .railfoot's margin-top:auto keeps the who/ERP chip pinned with no visible gap. | O10: None - verified with getComputedStyle, not just eyeballed. | P10: A Public | Q10: Built & verified | R10: Two segments totalling ~62 tool calls (162,610 tokens) across an initial 600s stall and one transient API disconnect, both recovered. | S10: The three .stat divs and their population code removed from index.html/app.js; .railfoot's margin-top:auto keeps the who/ERP chip pinned with no visible gap. | T10: None - verified with getComputedStyle, not just eyeballed. | U10: A Public
A11: A1 | B11: A Public | C11: E1 Access & Identity | D11: Split landing page | E11: One page, two halves: Decoder left, Directory right, Log in top-right. No credentials needed to use either half. | F11: Must | G11: 8 | H11: R1 | I11: Not started | J11: K1 | K11: The main page for everyone | L11: Built & verified | M11: Two segments totalling ~62 tool calls (162,610 tokens) across an initial 600s stall and one transient API disconnect, both recovered. | N11: Split landing page built as new web/public.html/js/css; responsive stack under 860px verified programmatically at innerWidth 767. | O11: None of note. | P11: A Public | Q11: Built & verified | R11: Two segments totalling ~62 tool calls (162,610 tokens) across an initial 600s stall and one transient API disconnect, both recovered. | S11: Split landing page built as new web/public.html/js/css; responsive stack under 860px verified programmatically at innerWidth 767. | T11: None of note. | U11: A Public
A12: A2 | B12: A Public | C12: E1 Access & Identity | D12: Decoder half | E12: Paste any code, get head, sub-head, group, every spec with its per-group label, vendor. 00 reads 'not applicable'. Malformed input explains why. | F12: Must | G12: 3 | H12: R1 | I12: Not started | J12: A1 | L12: Built & verified | M12: Two segments totalling ~62 tool calls (162,610 tokens) across an initial 600s stall and one transient API disconnect, both recovered. | N12: Decoder half verified against the brief's exact example (RMBS0010206100007) and against malformed/well-formed-but-unissued/unknown-group edge cases, all in plain English, none as raw error codes. | O12: None - matched the acceptance criteria precisely. | P12: A Public | Q12: Built & verified | R12: Two segments totalling ~62 tool calls (162,610 tokens) across an initial 600s stall and one transient API disconnect, both recovered. | S12: Decoder half verified against the brief's exact example (RMBS0010206100007) and against malformed/well-formed-but-unissued/unknown-group edge cases, all in plain English, none as raw error codes. | T12: None - matched the acceptance criteria precisely. | U12: A Public
A13: A4 | B13: A Public | C13: E1 Access & Identity | D13: Directory half | E13: Search 1,947 items by code, name or description. Row opens a read-only detail card. | F13: Must | G13: 5 | H13: R1 | I13: Not started | J13: A1 | L13: Built & verified | M13: Two segments totalling ~62 tool calls (162,610 tokens) across an initial 600s stall and one transient API disconnect, both recovered. | N13: Directory search verified for odonil (7 hits), battery (47 hits) and, notably, mseal (1 hit) - the last one only works because a dedicated, smaller normaliser squashes punctuation, since core.matcher.normalize() (tuned for fuzzy matching) keeps the hyphen in 'M-Seal' and would have missed it. | O13: Deviation: built a second, deliberately narrow text normaliser (_norm() in routes/public.py) rather than reuse core.matcher.normalize(), because that function's fuzzy-matching tuning doesn't serve a plain search box. Flagged in the handover as two different notions of 'the same text' now existing in the codebase - worth unifying later, not done here since it wasn't broken for either use case. | P13: A Public | Q13: Built & verified | R13: Two segments totalling ~62 tool calls (162,610 tokens) across an initial 600s stall and one transient API disconnect, both recovered. | S13: Directory search verified for odonil (7 hits), battery (47 hits) and, notably, mseal (1 hit) - the last one only works because a dedicated, smaller normaliser squashes punctuation, since core.matcher.normalize() (tuned for fuzzy matching) keeps the hyphen in 'M-Seal' and would have missed it. | T13: Deviation: built a second, deliberately narrow text normaliser (_norm() in routes/public.py) rather than reuse core.matcher.normalize(), because that function's fuzzy-matching tuning doesn't serve a plain search box. Flagged in the handover as two different notions of 'the same text' now existing in the codebase - worth unifying later, not done here since it wasn't broken for either use case. | U13: A Public
A14: A3 | B14: A Public | C14: E1 Access & Identity | D14: Dictionary browse | E14: Search 889 groups; open one to see its spec slots and values. Reachable from the directory half. | F14: Must | G14: 3 | H14: R1 | I14: Not started | J14: A4 | L14: Built & verified | M14: Two segments totalling ~62 tool calls (162,610 tokens) across an initial 600s stall and one transient API disconnect, both recovered. | N14: Dictionary browse built as tabs on the same directory panel; verified per-group spec labels differ correctly for the same slot number (Air Freshener slot 1 'Type' vs Battery Pack slot 1 'Form Factor'). | O14: None beyond the shared normaliser note above. | P14: A Public | Q14: Built & verified | R14: Two segments totalling ~62 tool calls (162,610 tokens) across an initial 600s stall and one transient API disconnect, both recovered. | S14: Dictionary browse built as tabs on the same directory panel; verified per-group spec labels differ correctly for the same slot number (Air Freshener slot 1 'Type' vs Battery Pack slot 1 'Form Factor'). | T14: None beyond the shared normaliser note above. | U14: A Public
A15: A8 | B15: B Auth | C15: E1 Access & Identity | D15: Server-side write protection | E15: Every mutating endpoint returns 401 to an unauthenticated caller invoked directly, not merely hidden in the interface. | F15: Must | G15: 3 | H15: R1 | I15: Not started | K15: The actual boundary | L15: Built & verified | M15: Two sessions totalling ~132 tool calls (376,028 tokens): the main build, then a second targeted session for the Secure-cookie fix flagged by Agent F. | N15: require_session/require_admin raise a typed ApiError caught centrally by the dispatcher; verified live with a bare curl call, no cookie, against a mutating endpoint - 401, not a hidden button. | O15: None - this was treated as the single highest-priority story in the whole packet and tested accordingly. | P15: B Auth | Q15: Built & verified | R15: Two sessions totalling ~132 tool calls (376,028 tokens): the main build, then a second targeted session for the Secure-cookie fix flagged by Agent F. | S15: require_session/require_admin raise a typed ApiError caught centrally by the dispatcher; verified live with a bare curl call, no cookie, against a mutating endpoint - 401, not a hidden button. | T15: None - this was treated as the single highest-priority story in the whole packet and tested accordingly. | U15: B Auth
A16: A5 | B16: B Auth | C16: E1 Access & Identity | D16: Login | E16: Username and password against the user table, scrypt hashed. Bad credentials give one generic message. | F16: Must | G16: 5 | H16: R2 | I16: Not started | J16: A8 | K16: Simple by instruction | L16: Built & verified | M16: Two sessions totalling ~132 tool calls (376,028 tokens): the main build, then a second targeted session for the Secure-cookie fix flagged by Agent F. | N16: scrypt + per-user salt, hmac.compare_digest comparison, byte-identical response for a wrong username vs a wrong password (verified with curl against both cases), and a dummy hash computed even for an unknown username so there's no timing tell either. | O16: None of note. | P16: B Auth | Q16: Built & verified | R16: Two sessions totalling ~132 tool calls (376,028 tokens): the main build, then a second targeted session for the Secure-cookie fix flagged by Agent F. | S16: scrypt + per-user salt, hmac.compare_digest comparison, byte-identical response for a wrong username vs a wrong password (verified with curl against both cases), and a dummy hash computed even for an unknown username so there's no timing tell either. | T16: None of note. | U16: B Auth
A17: A6 | B17: B Auth | C17: E1 Access & Identity | D17: Session handling | E17: HMAC-signed HttpOnly cookie, 12h expiry, logout clears it. Expiry returns to the landing page, never a blank screen. | F17: Must | G17: 3 | H17: R2 | I17: Not started | J17: A5 | L17: Built & verified (design reversed) | M17: Two sessions totalling ~132 tool calls (376,028 tokens): the main build, then a second targeted session for the Secure-cookie fix flagged by Agent F. | N17: Sessions built as HttpOnly + SameSite=Strict + Secure cookies as the plan's acceptance criteria describes ('HMAC-signed HttpOnly cookie'), using a random token whose hash (not the token itself) is stored server-side. | O17: Real deviation, caught late: Secure was set unconditionally, which a real browser will never send back over the plain-HTTP local server that is the app's actual default deployment path - nobody could stay logged in against the app as it runs today. Agent F caught this in live testing; mediated by adding a config.json 'tls' flag (default false) that gates the Secure attribute, verified with both curl and a real Chrome round-trip including a fresh page navigation. | P17: B Auth | Q17: Built & verified (design reversed) | R17: Two sessions totalling ~132 tool calls (376,028 tokens): the main build, then a second targeted session for the Secure-cookie fix flagged by Agent F. | S17: Sessions built as HttpOnly + SameSite=Strict + Secure cookies as the plan's acceptance criteria describes ('HMAC-signed HttpOnly cookie'), using a random token whose hash (not the token itself) is stored server-side. | T17: Real deviation, caught late: Secure was set unconditionally, which a real browser will never send back over the plain-HTTP local server that is the app's actual default deployment path - nobody could stay logged in against the app as it runs today. Agent F caught this in live testing; mediated by adding a config.json 'tls' flag (default false) that gates the Secure attribute, verified with both curl and a real Chrome round-trip including a fresh page navigation. | U17: B Auth
A18: A9 | B18: B Auth | C18: E1 Access & Identity | D18: Attribution from session | E18: created_by comes from the session. The forgeable X-User header is deleted from the codebase. | F18: Must | G18: 2 | H18: R2 | I18: Not started | J18: A6 | K18: Closes a real hole | L18: Built & verified | M18: Two sessions totalling ~132 tool calls (376,028 tokens): the main build, then a second targeted session for the Secure-cookie fix flagged by Agent F. | N18: grep -rn X-User returns only two explanatory comments, no functional usage anywhere. Attribution now flows from the session, resolved once per request inside core/dispatch.py's existing lock. | O18: Deviation: fixing this required editing core/dispatch.py, which Agent 0 (not Agent B) owns. Mediated by doing the narrowest possible change (one block, inside the existing lock region) and being explicit about it in the handover rather than silently reaching into another agent's file - exactly the CONTRACTS.md house rule about not silently editing someone else's file. | P18: B Auth | Q18: Built & verified | R18: Two sessions totalling ~132 tool calls (376,028 tokens): the main build, then a second targeted session for the Secure-cookie fix flagged by Agent F. | S18: grep -rn X-User returns only two explanatory comments, no functional usage anywhere. Attribution now flows from the session, resolved once per request inside core/dispatch.py's existing lock. | T18: Deviation: fixing this required editing core/dispatch.py, which Agent 0 (not Agent B) owns. Mediated by doing the narrowest possible change (one block, inside the existing lock region) and being explicit about it in the handover rather than silently reaching into another agent's file - exactly the CONTRACTS.md house rule about not silently editing someone else's file. | U18: B Auth
A19: A7 | B19: B Auth | C19: E1 Access & Identity | D19: Creator shell | E19: After login: Create, Item master, Activity. The landing page stays reachable while logged in. | F19: Must | G19: 3 | H19: R2 | I19: Not started | J19: A6 | L19: Built & verified | M19: Two sessions totalling ~132 tool calls (376,028 tokens): the main build, then a second targeted session for the Secure-cookie fix flagged by Agent F. | N19: Post-login shell reachable via the existing app.js nav; landing page stays reachable while logged in (nothing in the public routes checks a session). | O19: None beyond what's already covered under A9/A6's app.js changes. | P19: B Auth | Q19: Built & verified | R19: Two sessions totalling ~132 tool calls (376,028 tokens): the main build, then a second targeted session for the Secure-cookie fix flagged by Agent F. | S19: Post-login shell reachable via the existing app.js nav; landing page stays reachable while logged in (nothing in the public routes checks a session). | T19: None beyond what's already covered under A9/A6's app.js changes. | U19: B Auth
A20: A10 | B20: B Auth | C20: E1 Access & Identity | D20: User management | E20: manage.py adduser / disable / resetpw. At least one active creator must always remain. | F20: Must | G20: 3 | H20: R2 | I20: Not started | J20: A5 | K20: CLI is enough at this size | L20: Built & verified | M20: Two sessions totalling ~132 tool calls (376,028 tokens): the main build, then a second targeted session for the Secure-cookie fix flagged by Agent F. | N20: manage.py adduser/disable/resetpw/listusers all work; disable on the last active admin is refused, verified live, then succeeds once a second admin exists. | O20: manage.py didn't exist yet when this agent started (the file's overall ownership per agents/README.md sits with Agent H, but the brief explicitly carved out 'user commands only' for this agent). Structured with argparse sub-parsers specifically so Agent H could extend it without touching these commands - which is exactly what happened. | P20: B Auth | Q20: Built & verified | R20: Two sessions totalling ~132 tool calls (376,028 tokens): the main build, then a second targeted session for the Secure-cookie fix flagged by Agent F. | S20: manage.py adduser/disable/resetpw/listusers all work; disable on the last active admin is refused, verified live, then succeeds once a second admin exists. | T20: manage.py didn't exist yet when this agent started (the file's overall ownership per agents/README.md sits with Agent H, but the brief explicitly carved out 'user commands only' for this agent). Structured with argparse sub-parsers specifically so Agent H could extend it without touching these commands - which is exactly what happened. | U20: B Auth
A21: S1 | B21: B Auth | C21: E1 Access & Identity | D21: Settings screen with the API key | E21: Admin-only. match.mode fuzzy|llm toggle, provider, API key as a write-only password field, model, threshold, erp flags, sync times. Key never returned to the client. With no key the app runs fuzzy-only and says so. | F21: Must | G21: 8 | H21: R2 | I21: Not started | J21: A5 | K21: Anuraag pastes the key himself | L21: Built & verified | M21: Two sessions totalling ~132 tool calls (376,028 tokens): the main build, then a second targeted session for the Secure-cookie fix flagged by Agent F. | N21: Settings screen live: match.mode toggle, provider, write-only API-key field (masked on read, never echoed), model, threshold, ERP flags, sync times. Clearing the key snaps match.mode back to fuzzy automatically, not just in the UI - verified live. 'Test key' surfaces the provider's real error text (tested against a deliberately wrong Anthropic key, got the real 401 back, not a crash). | O21: Judgement call: CONTRACTS.md's route-ownership table names /settings/* as the prefix, but the dispatcher only ever routes a path starting with /api/ through the table at all - a bare /settings GET could never have reached a handler as Agent 0 built it. Implemented under /api/v1/settings instead, consistent with the brief's own task list, and flagged the discrepancy rather than silently picking one reading. | P21: B Auth | Q21: Built & verified | R21: Two sessions totalling ~132 tool calls (376,028 tokens): the main build, then a second targeted session for the Secure-cookie fix flagged by Agent F. | S21: Settings screen live: match.mode toggle, provider, write-only API-key field (masked on read, never echoed), model, threshold, ERP flags, sync times. Clearing the key snaps match.mode back to fuzzy automatically, not just in the UI - verified live. 'Test key' surfaces the provider's real error text (tested against a deliberately wrong Anthropic key, got the real 401 back, not a crash). | T21: Judgement call: CONTRACTS.md's route-ownership table names /settings/* as the prefix, but the dispatcher only ever routes a path starting with /api/ through the table at all - a bare /settings GET could never have reached a handler as Agent 0 built it. Implemented under /api/v1/settings instead, consistent with the brief's own task list, and flagged the discrepancy rather than silently picking one reading. | U21: B Auth
A22: A11 | B22: B Auth | C22: E1 Access & Identity | D22: Change own password | E22: A logged-in creator can change their password; the old one is required. | F22: Should | G22: 2 | H22: R2 | I22: Not started | J22: A5 | L22: Built & verified | M22: Two sessions totalling ~132 tool calls (376,028 tokens): the main build, then a second targeted session for the Secure-cookie fix flagged by Agent F. | N22: POST /api/v1/auth/password requires the old password, enforces an 8-character minimum, clears any forced-change flag on success. | O22: Extended slightly beyond the literal spec: also applied after manage.py resetpw, not just the first-run bootstrap, on the reasoning that 'hand the password over directly' is safer if the recipient is then made to pick their own. Flagged as easy to drop if unwanted. | P22: B Auth | Q22: Built & verified | R22: Two sessions totalling ~132 tool calls (376,028 tokens): the main build, then a second targeted session for the Secure-cookie fix flagged by Agent F. | S22: POST /api/v1/auth/password requires the old password, enforces an 8-character minimum, clears any forced-change flag on success. | T22: Extended slightly beyond the literal spec: also applied after manage.py resetpw, not just the first-run bootstrap, on the reasoning that 'hand the password over directly' is safer if the recipient is then made to pick their own. Flagged as easy to drop if unwanted. | U22: B Auth
A23: C10 | B23: E Create | C23: E3 Code Engine | D23: Create screen with the three phases | E23: Paste or upload, then every line shows what phase 1 found, which group phase 2 chose, and what phase 3 read into each slot. | F23: Must | G23: 5 | H23: R3 | I23: Not started | J23: A7 | K23: Engine exists; this is the gated screen | L23: Built & verified | M23: Session cut off by the account spend-limit event while writing its handover note; the file had already been fully written to disk before the connection died, and verification found nothing missing, so it was not resumed further. | N23: Create screen built with all three phases shown per card; resolve fires one request per line concurrently (pool of 4) so a card renders the moment its own request lands, rather than waiting for a single 20-line round trip to finish entirely. | O23: Deviation from the literal 'one round trip' reading: chose 20 concurrent single-line requests over one server-side batch call, explicitly traded off for faster perceived responsiveness. resolve_batch still exists for any caller that prefers the single-round-trip behaviour. | P23: E Create | Q23: Built & verified | R23: Session cut off by the account spend-limit event while writing its handover note; the file had already been fully written to disk before the connection died, and verification found nothing missing, so it was not resumed further. | S23: Create screen built with all three phases shown per card; resolve fires one request per line concurrently (pool of 4) so a card renders the moment its own request lands, rather than waiting for a single 20-line round trip to finish entirely. | T23: Deviation from the literal 'one round trip' reading: chose 20 concurrent single-line requests over one server-side batch call, explicitly traded off for faster perceived responsiveness. resolve_batch still exists for any caller that prefers the single-round-trip behaviour. | U23: E Create
A24: F8 | B24: E Create | C24: E5 Invoice & OCR | D24: Invoice upload wired into Create | E24: Drop a PDF, scan, photo, Excel or CSV and get one row per line item, each resolving independently. | F24: Must | G24: 5 | H24: R3 | I24: Not started | J24: C10 | K24: Engine exists | L24: Built & verified | M24: Session cut off by the account spend-limit event while writing its handover note; the file had already been fully written to disk before the connection died, and verification found nothing missing, so it was not resumed further. | N24: Invoice upload wired in; verified vendor is read only from the invoice line itself, never the header, per Anuraag's explicit rule. | O24: None of note. | P24: E Create | Q24: Built & verified | R24: Session cut off by the account spend-limit event while writing its handover note; the file had already been fully written to disk before the connection died, and verification found nothing missing, so it was not resumed further. | S24: Invoice upload wired in; verified vendor is read only from the invoice line itself, never the header, per Anuraag's explicit rule. | T24: None of note. | U24: E Create
A25: K3 | B25: E Create | C25: E6 Master & Restructure | D25: Conditional cascading dropdowns | E25: Choosing a head filters sub-heads to that head. Choosing a sub-head filters groups to that sub-head only. Choosing a group re-renders its spec slots with that group's labels. | F25: Must | G25: 8 | H25: R3 | I25: Not started | J25: C10 | K25: Core of your edit requirement | L25: Built & verified | M25: Session cut off by the account spend-limit event while writing its handover note; the file had already been fully written to disk before the connection died, and verification found nothing missing, so it was not resumed further. | N25: Cascading dropdowns filter strictly to their parent at every level (CONTRACTS.md's 'impossible to choose, not merely discouraged'); choosing a group re-renders spec boxes with that group's own labels, verified live changing sub-head clears the group and shortens the code live via /resolve/preview. | O25: None of note. | P25: E Create | Q25: Built & verified | R25: Session cut off by the account spend-limit event while writing its handover note; the file had already been fully written to disk before the connection died, and verification found nothing missing, so it was not resumed further. | S25: Cascading dropdowns filter strictly to their parent at every level (CONTRACTS.md's 'impossible to choose, not merely discouraged'); choosing a group re-renders spec boxes with that group's own labels, verified live changing sub-head clears the group and shortens the code live via /resolve/preview. | T25: None of note. | U25: E Create
A26: K4 | B26: D Engine | C26: E6 Master & Restructure | D26: Live code recomputation | E26: Any change to head, sub-head, group, spec or vendor recomputes the code immediately, obeying the interior-00 and trailing-truncate rules. | F26: Must | G26: 5 | H26: R3 | I26: Not started | J26: K3 | L26: Built & verified | M26: Single successful segment: 61 tool calls, 199,839 tokens, ~17 min. | N26: preview_code(con, head_id, subhead_id, grp_id, slots, vendor) built pure and side-effect-free, with a per-position explain list; every value is resolved through assemble() itself, never reimplemented. | O26: The brief named this function; CONTRACTS.md's frozen core/codes.py signatures technically don't list it (only assemble/parse/next_group_code are frozen there) - built it anyway since the brief was explicit and it's additive, not a change to a frozen signature. | P26: D Engine | Q26: Built & verified | R26: Single successful segment: 61 tool calls, 199,839 tokens, ~17 min. | S26: preview_code(con, head_id, subhead_id, grp_id, slots, vendor) built pure and side-effect-free, with a per-position explain list; every value is resolved through assemble() itself, never reimplemented. | T26: The brief named this function; CONTRACTS.md's frozen core/codes.py signatures technically don't list it (only assemble/parse/next_group_code are frozen there) - built it anyway since the brief was explicit and it's additive, not a change to a frozen signature. | U26: D Engine
A27: K11 | B27: D Engine | C27: E3 Code Engine | D27: Item-level number reservation | E27: Moving an item to another group frees its old position under that head and sub-head into the vacancy ledger. New arrivals take a fresh number; the reserved one is released only to a later item with the same spec tuple, and dropped when the sub-head is revoked. | F27: Must | G27: 8 | H27: R3 | I27: Not started | J27: K4 | K27: The logic you said was missing | L27: Built & verified (design reversed) | M27: Single successful segment: 61 tool calls, 199,839 tokens, ~17 min. | N27: Item-level vacancy was genuinely missing before this session; built from scratch (next_item_position, free_item_position, item_vacancy writes on every non-frozen recode). | O27: The plan row's own acceptance text ('released only to a >=88% name match') describes the OLD reservation rule. This session implements the newer, opposite rule Anuraag specified on 6 August - queue-claim, lowest-first, no semantic matching at all. This is the same class of deviation as D9: intentional, instructed, and the plan text is simply stale relative to CONTRACTS.md, which is dated the same day but reflects a later decision. | P27: D Engine | Q27: Built & verified (design reversed) | R27: Single successful segment: 61 tool calls, 199,839 tokens, ~17 min. | S27: Item-level vacancy was genuinely missing before this session; built from scratch (next_item_position, free_item_position, item_vacancy writes on every non-frozen recode). | T27: The plan row's own acceptance text ('released only to a >=88% name match') describes the OLD reservation rule. This session implements the newer, opposite rule Anuraag specified on 6 August - queue-claim, lowest-first, no semantic matching at all. This is the same class of deviation as D9: intentional, instructed, and the plan text is simply stale relative to CONTRACTS.md, which is dated the same day but reflects a later decision. | U27: D Engine
A28: K12 | B28: F Master | C28: E6 Master & Restructure | D28: Vacancy visibility | E28: Reserved numbers at both group and item level are listed with what freed them and what would claim them. | F28: Should | G28: 3 | H28: R4 | I28: Not started | J28: K11 | L28: Built & verified | M28: Single successful segment: 64 tool calls, 246,199 tokens, ~19.5 min. | N28: list_vacancies(con) built by Agent D, consumed here; verified end-to-end by creating a throwaway group, deleting it, and watching the vacancy appear correctly with the right 'freed by' text. | O28: Presented as 'next free number' rather than 'reserved for' per the queue-claim rule - the plan row's own wording ('what would claim them') reads closer to the old reservation semantics, adjusted in the copy to avoid being misleading now that vacancies aren't held for anyone specific. | P28: F Master | Q28: Built & verified | R28: Single successful segment: 64 tool calls, 246,199 tokens, ~19.5 min. | S28: list_vacancies(con) built by Agent D, consumed here; verified end-to-end by creating a throwaway group, deleting it, and watching the vacancy appear correctly with the right 'freed by' text. | T28: Presented as 'next free number' rather than 'reserved for' per the queue-claim rule - the plan row's own wording ('what would claim them') reads closer to the old reservation semantics, adjusted in the copy to avoid being misleading now that vacancies aren't held for anyone specific. | U28: F Master
A29: K5 | B29: E Create | C29: E6 Master & Restructure | D29: Edit before submit | E29: Every proposed code carries an Edit control. Nothing is written until Submit. | F29: Must | G29: 3 | H29: R3 | I29: Not started | J29: K4 | L29: Built & verified | M29: Session cut off by the account spend-limit event while writing its handover note; the file had already been fully written to disk before the connection died, and verification found nothing missing, so it was not resumed further. | N29: Edit-before-submit enforced; Submit stays disabled while any blocker stands. | O29: None. | P29: E Create | Q29: Built & verified | R29: Session cut off by the account spend-limit event while writing its handover note; the file had already been fully written to disk before the connection died, and verification found nothing missing, so it was not resumed further. | S29: Edit-before-submit enforced; Submit stays disabled while any blocker stands. | T29: None. | U29: E Create
A30: B5 | B30: E Create | C30: E2 API v1 | D30: Idempotent commit | E30: A commit carries a client token; replaying it returns the original code instead of issuing a second. | F30: Must | G30: 3 | H30: R3 | I30: Not started | J30: K5 | K30: Guards double-click | L30: Built & verified | M30: Session cut off by the account spend-limit event while writing its handover note; the file had already been fully written to disk before the connection died, and verification found nothing missing, so it was not resumed further. | N30: Idempotency key required on commit; two identical commits with the same key verified to mint only one item, the second returning the same code with idempotent:true. | O30: Deviation: stored the key-to-result mapping in the existing audit table rather than a new dedicated table, since Agent 0 owns core/db.py's schema exclusively and this didn't need a schema change to work. Flagged as a candidate for a purpose-built table later if it needs to scale. | P30: E Create | Q30: Built & verified | R30: Session cut off by the account spend-limit event while writing its handover note; the file had already been fully written to disk before the connection died, and verification found nothing missing, so it was not resumed further. | S30: Idempotency key required on commit; two identical commits with the same key verified to mint only one item, the second returning the same code with idempotent:true. | T30: Deviation: stored the key-to-result mapping in the existing audit table rather than a new dedicated table, since Agent 0 owns core/db.py's schema exclusively and this didn't need a schema change to work. Flagged as a candidate for a purpose-built table later if it needs to scale. | U30: E Create
A31: C8 | B31: D Engine | C31: E3 Code Engine | D31: Concurrent issuance safety | E31: Two creators submitting in the same second cannot receive the same code. Proven by a concurrent test, not by argument. | F31: Must | G31: 5 | H31: R5 | I31: Not started | J31: B5 | L31: Built & verified | M31: Single successful segment: 61 tool calls, 199,839 tokens, ~17 min. | N31: tests/test_concurrent.py fires 20 threads at the allocator and asserts 20 distinct, gapless codes - a real, runnable proof, not an argument. Caught and fixed one genuine race in mint_from_lease along the way (two threads minting from the same lease produced the same number before the fix). | O31: The concurrency test is exactly what caught the lease race - a clean example of a test paying for itself immediately rather than being a formality. | P31: D Engine | Q31: Built & verified | R31: Single successful segment: 61 tool calls, 199,839 tokens, ~17 min. | S31: tests/test_concurrent.py fires 20 threads at the allocator and asserts 20 distinct, gapless codes - a real, runnable proof, not an argument. Caught and fixed one genuine race in mint_from_lease along the way (two threads minting from the same lease produced the same number before the fix). | T31: The concurrency test is exactly what caught the lease race - a clean example of a test paying for itself immediately rather than being a formality. | U31: D Engine
A32: K6 | B32: F Master | C32: E6 Master & Restructure | D32: Item master as an editable directory | E32: Same rows and columns as the public directory, every field editable in place, with the same cascading dropdowns. | F32: Must | G32: 8 | H32: R4 | I32: Not started | J32: K3 | K32: Your instruction | L32: Built & verified | M32: Single successful segment: 64 tool calls, 246,199 tokens, ~19.5 min. | N32: Item master rebuilt as an editable directory with server-side pagination (1,947+ rows never all loaded at once) and the same cascading filters as the create screen. | O32: Judgement call, explicitly flagged: the brief's task 1 asks for 'the same cascading dropdowns as the create screen' in the same sentence as 'field edits never change the code' - read literally, a reclassifying cascade on the edit form would contradict that same sentence. Resolved by putting the cascade on the filter toolbar (narrowing the list) and keeping the edit form to non-code-derived fields only, with reclassification staying where it already lived (the group move/merge routes). Documented as reversible in a few lines if Anuraag meant it literally. | P32: F Master | Q32: Built & verified | R32: Single successful segment: 64 tool calls, 246,199 tokens, ~19.5 min. | S32: Item master rebuilt as an editable directory with server-side pagination (1,947+ rows never all loaded at once) and the same cascading filters as the create screen. | T32: Judgement call, explicitly flagged: the brief's task 1 asks for 'the same cascading dropdowns as the create screen' in the same sentence as 'field edits never change the code' - read literally, a reclassifying cascade on the edit form would contradict that same sentence. Resolved by putting the cascade on the filter toolbar (narrowing the list) and keeping the edit form to non-code-derived fields only, with reclassification staying where it already lived (the group move/merge routes). Documented as reversible in a few lines if Anuraag meant it literally. | U32: F Master
A33: K7 | B33: F Master | C33: E6 Master & Restructure | D33: Revision history | E33: Every save snapshots the whole row with who, when and what changed. Nothing is overwritten in place. | F33: Must | G33: 8 | H33: R4 | I33: Not started | J33: K6 | K33: The version-control requirement | L33: Built & verified | M33: Single successful segment: 64 tool calls, 246,199 tokens, ~19.5 min. | N33: core/versions.py built: whole-row snapshots (never diffs) on every save, with a lazy ensure_baseline() so the 1,947 pre-existing items get a real 'version 1' the first time they're touched rather than needing a slow bulk migration. | O33: None of note. | P33: F Master | Q33: Built & verified | R33: Single successful segment: 64 tool calls, 246,199 tokens, ~19.5 min. | S33: core/versions.py built: whole-row snapshots (never diffs) on every save, with a lazy ensure_baseline() so the 1,947 pre-existing items get a real 'version 1' the first time they're touched rather than needing a slow bulk migration. | T33: None of note. | U33: F Master
A34: K8 | B34: F Master | C34: E6 Master & Restructure | D34: Revert to a previous version | E34: Any earlier version can be restored in one click. The revert is itself a new version, so it can be undone too. | F34: Must | G34: 5 | H34: R4 | I34: Not started | J34: K7 | L34: Built & verified | M34: Single successful segment: 64 tool calls, 246,199 tokens, ~19.5 min. | N34: Revert writes the target version's contents as a new version rather than deleting history; verified live - reverting to version 1 three times in testing produced versions 3, 5 and 6, never shrinking the history. | O34: None of note. | P34: F Master | Q34: Built & verified | R34: Single successful segment: 64 tool calls, 246,199 tokens, ~19.5 min. | S34: Revert writes the target version's contents as a new version rather than deleting history; verified live - reverting to version 1 three times in testing produced versions 3, 5 and 6, never shrinking the history. | T34: None of note. | U34: F Master
A35: K9 | B35: F Master | C35: E6 Master & Restructure | D35: Activity feed with diffs | E35: Activity shows field-level before and after, filterable by person, item and date, with Revert on each entry. | F35: Must | G35: 5 | H35: R4 | I35: Not started | J35: K7 | L35: Built & verified | M35: Single successful segment: 64 tool calls, 246,199 tokens, ~19.5 min. | N35: Activity feed merges item_version diffs and audit rows into one timestamp-sorted feed with real field-level before/after, filterable by person/item/date, Revert on each entry. | O35: matched_by extraction from audit.detail is speculative - built against a guess at the shape since Agent E's commit-logging (which is what would populate it) hadn't landed yet when this was built; documented as a likely one-line fix once that lands, rather than blocking on it. | P35: F Master | Q35: Built & verified | R35: Single successful segment: 64 tool calls, 246,199 tokens, ~19.5 min. | S35: Activity feed merges item_version diffs and audit rows into one timestamp-sorted feed with real field-level before/after, filterable by person/item/date, Revert on each entry. | T35: matched_by extraction from audit.detail is speculative - built against a guess at the shape since Agent E's commit-logging (which is what would populate it) hadn't landed yet when this was built; documented as a likely one-line fix once that lands, rather than blocking on it. | U35: F Master
A36: G3 | B36: F Master | C36: E6 Master & Restructure | D36: Move, merge, retire, rename | E36: Each shows a full impact preview listing what re-codes and what stays frozen. | F36: Must | G36: 8 | H36: S0 | I36: Done | K36: Built and tested on group Tissue | L36: Duplicate of D Engine's G3 | M36: Single successful segment: 64 tool calls, 246,199 tokens, ~19.5 min. | N36: See D Engine row above - same story. | O36: N/A. | P36: F Master | Q36: Pre-existing, extended/re-verified | R36: Single successful segment: 64 tool calls, 246,199 tokens, ~19.5 min. | S36: Move/merge/retire/rename already worked with impact previews; updated for the new queue-claim numbering and re-verified against the exact worked example in the brief - moving group Tissue from House Keeping to Stationery still previews as 1 recode, 7 frozen, 041 freed. | T36: Also fixed a real, previously-latent bug while in this code: the old 'used numbers' query had no status='active' filter, so a retired group's number blocked forever and could never actually be claimed by anyone - discovered only because queue-claim made the bug's effect directly visible for the first time. | U36: F Master
A37: K10 | B37: F Master | C37: E6 Master & Restructure | D37: Revert respects frozen codes | E37: A revert never rewrites a code that is live in ERPNext. It restores fields and says plainly what it could not restore. | F37: Must | G37: 5 | H37: R4 | I37: Not started | J37: K8 | K37: Where version control meets freeze-on-first-use | L37: Built & verified | M37: Single successful segment: 64 tool calls, 246,199 tokens, ~19.5 min. | N37: The frozen-code revert interaction verified with a real in_erp item: restores every other field, explicitly refuses the code, and reports 'Restored 1 field. The code ... was not changed - it is live in ERPNext and is permanent' - matching the contract's example message almost verbatim. | O37: Caught a genuine bug during this exact testing: the first draft counted updated_at as a 'restored field' since that timestamp always differs from the target snapshot, and briefly wrote it backwards before being overwritten two lines later. Fixed by excluding it from the comparison. This is precisely the kind of silent over-claimed revert the brief warns about, caught only because a real revert was run against a real row and the field count was actually read, not just inspected by eye. Also: the seeded DB had no item with two different codes across its version history yet (the feature is brand new), so this exact path was proven with a fabricated fixture, deliberately reverted back to the true original afterward through the real snapshot/log path so the correction is itself an honest version, not a silent rewrite. | P37: F Master | Q37: Built & verified | R37: Single successful segment: 64 tool calls, 246,199 tokens, ~19.5 min. | S37: The frozen-code revert interaction verified with a real in_erp item: restores every other field, explicitly refuses the code, and reports 'Restored 1 field. The code ... was not changed - it is live in ERPNext and is permanent' - matching the contract's example message almost verbatim. | T37: Caught a genuine bug during this exact testing: the first draft counted updated_at as a 'restored field' since that timestamp always differs from the target snapshot, and briefly wrote it backwards before being overwritten two lines later. Fixed by excluding it from the comparison. This is precisely the kind of silent over-claimed revert the brief warns about, caught only because a real revert was run against a real row and the field count was actually read, not just inspected by eye. Also: the seeded DB had no item with two different codes across its version history yet (the feature is brand new), so this exact path was proven with a fabricated fixture, deliberately reverted back to the true original afterward through the real snapshot/log path so the correction is itself an honest version, not a silent rewrite. | U37: F Master
A38: G5 | B38: F Master | C38: E6 Master & Restructure | D38: Excel export | E38: Item_Master, Item_Code_Master, Code_Mapping and Audit_Trail in one workbook. | F38: Must | G38: 5 | H38: S0 | I38: Done | L38: Pre-existing, kept working | M38: Single successful segment: 64 tool calls, 246,199 tokens, ~19.5 min. | N38: Excel export (four sheets) already existed; kept working unchanged through the whole master rebuild - sheet names and column shape untouched, as the brief required. | O38: None. | P38: F Master | Q38: Pre-existing, kept working | R38: Single successful segment: 64 tool calls, 246,199 tokens, ~19.5 min. | S38: Excel export (four sheets) already existed; kept working unchanged through the whole master rebuild - sheet names and column shape untouched, as the brief required. | T38: None. | U38: F Master
A39: B1 | B39: H Deploy | C39: E2 API v1 | D39: Version and freeze the contract | E39: Everything served under /api/v1 exactly as the PDR documents it. | F39: Must | G39: 5 | H39: R5 | I39: Not started | J39: A8 | K39: So the larger system can build against it | L39: Built & verified | M39: Final segment: 60 tool calls, 293,205 tokens, ~12 min (again, an earlier segment building the installer and starting VPS assets failed on the spend-limit before reporting usage). | N39: Every /api/v1 route across all six modules checked against ok()/err() usage - all correct. routes/meta.py's /api/docs is generated live from the actual route table on every request (method, path, and auth requirement via source introspection), not hand-maintained. | O39: None of note. | P39: H Deploy | Q39: Built & verified | R39: Final segment: 60 tool calls, 293,205 tokens, ~12 min (again, an earlier segment building the installer and starting VPS assets failed on the spend-limit before reporting usage). | S39: Every /api/v1 route across all six modules checked against ok()/err() usage - all correct. routes/meta.py's /api/docs is generated live from the actual route table on every request (method, path, and auth requirement via source introspection), not hand-maintained. | T39: None of note. | U39: H Deploy
A40: B2 | B40: H Deploy | C40: E2 API v1 | D40: Uniform error envelope | E40: Every failure returns ok:false with a stable machine code. No stack traces reach the client. | F40: Must | G40: 3 | H40: R5 | I40: Not started | J40: B1 | L40: Built & verified | M40: Final segment: 60 tool calls, 293,205 tokens, ~12 min (again, an earlier segment building the installer and starting VPS assets failed on the spend-limit before reporting usage). | N40: Uniform error envelope was Agent 0's foundational work, re-confirmed here as part of the full-system smoke suite (86/86 passing). | O40: None. | P40: H Deploy | Q40: Built & verified | R40: Final segment: 60 tool calls, 293,205 tokens, ~12 min (again, an earlier segment building the installer and starting VPS assets failed on the spend-limit before reporting usage). | S40: Uniform error envelope was Agent 0's foundational work, re-confirmed here as part of the full-system smoke suite (86/86 passing). | T40: None. | U40: H Deploy
A41: B3 | B41: H Deploy | C41: E2 API v1 | D41: Self-served API docs | E41: GET /api/docs lists every endpoint with request and response examples. | F41: Should | G41: 3 | H41: R5 | I41: Not started | J41: B1 | L41: Built & verified | M41: Final segment: 60 tool calls, 293,205 tokens, ~12 min (again, an earlier segment building the installer and starting VPS assets failed on the spend-limit before reporting usage). | N41: /api/docs live, HTML and ?format=json, generated from the route table so it can't go stale relative to the code actually running. | O41: None. | P41: H Deploy | Q41: Built & verified | R41: Final segment: 60 tool calls, 293,205 tokens, ~12 min (again, an earlier segment building the installer and starting VPS assets failed on the spend-limit before reporting usage). | S41: /api/docs live, HTML and ?format=json, generated from the route table so it can't go stale relative to the code actually running. | T41: None. | U41: H Deploy
...

Sheet Runs
A1: Build runs — one sitting, today
A2: Points roll up from the Delivery Plan. Each run ends with something you can open and use.
A4: Run | B4: What it delivers | C4: Points | D4: Stories | E4: Done | F4: Complete %
A5: S0 | B5: Already built: the grammar, all three phases, matching, invoice extraction, the master, restructuring, export, ERP read | C5: =SUMIFS('Delivery Plan'!$G:$G,'Delivery Plan'!$H:$H,$A5) | D5: =COUNTIFS('Delivery Plan'!$H:$H,$A5) | E5: =SUMIFS('Delivery Plan'!$G:$G,'Delivery Plan'!$H:$H,$A5,'Delivery Plan'!$I:$I,"Done") | F5: =IFERROR(E5/C5,0)
A6: R1 | B6: MiniMines theme and logo, the split landing page — decoder one side, directory the other, log in on top. Stats block removed | C6: =SUMIFS('Delivery Plan'!$G:$G,'Delivery Plan'!$H:$H,$A6) | D6: =COUNTIFS('Delivery Plan'!$H:$H,$A6) | E6: =SUMIFS('Delivery Plan'!$G:$G,'Delivery Plan'!$H:$H,$A6,'Delivery Plan'!$I:$I,"Done") | F6: =IFERROR(E6/C6,0)
A7: R2 | B7: Login, sessions, attribution from the session, user management, the creator shell behind the gate | C7: =SUMIFS('Delivery Plan'!$G:$G,'Delivery Plan'!$H:$H,$A7) | D7: =COUNTIFS('Delivery Plan'!$H:$H,$A7) | E7: =SUMIFS('Delivery Plan'!$G:$G,'Delivery Plan'!$H:$H,$A7,'Delivery Plan'!$I:$I,"Done") | F7: =IFERROR(E7/C7,0)
A8: R3 | B8: The create screen: paste or upload an invoice, three phases shown per line, cascading head-sub-head-group dropdowns, live code recomputation, edit before submit | C8: =SUMIFS('Delivery Plan'!$G:$G,'Delivery Plan'!$H:$H,$A8) | D8: =COUNTIFS('Delivery Plan'!$H:$H,$A8) | E8: =SUMIFS('Delivery Plan'!$G:$G,'Delivery Plan'!$H:$H,$A8,'Delivery Plan'!$I:$I,"Done") | F8: =IFERROR(E8/C8,0)
A9: R4 | B9: Item master as a fully editable directory, revision history on every save, one-click revert, activity feed with field-level diffs | C9: =SUMIFS('Delivery Plan'!$G:$G,'Delivery Plan'!$H:$H,$A9) | D9: =COUNTIFS('Delivery Plan'!$H:$H,$A9) | E9: =SUMIFS('Delivery Plan'!$G:$G,'Delivery Plan'!$H:$H,$A9,'Delivery Plan'!$I:$I,"Done") | F9: =IFERROR(E9/C9,0)
A10: R5 | B10: API frozen at /api/v1 with a real error contract, smoke suite, deployed to the internal server, starts on boot, daily backup | C10: =SUMIFS('Delivery Plan'!$G:$G,'Delivery Plan'!$H:$H,$A10) | D10: =COUNTIFS('Delivery Plan'!$H:$H,$A10) | E10: =SUMIFS('Delivery Plan'!$G:$G,'Delivery Plan'!$H:$H,$A10,'Delivery Plan'!$I:$I,"Done") | F10: =IFERROR(E10/C10,0)
A11: NEEDS INPUT | B11: Blocked on something only you or the organisation can supply — see the next tab | C11: =SUMIFS('Delivery Plan'!$G:$G,'Delivery Plan'!$H:$H,$A11) | D11: =COUNTIFS('Delivery Plan'!$H:$H,$A11) | E11: =SUMIFS('Delivery Plan'!$G:$G,'Delivery Plan'!$H:$H,$A11,'Delivery Plan'!$I:$I,"Done") | F11: =IFERROR(E11/C11,0)
A12: BACKLOG | B12: Agreed but not needed for go-live | C12: =SUMIFS('Delivery Plan'!$G:$G,'Delivery Plan'!$H:$H,$A12) | D12: =COUNTIFS('Delivery Plan'!$H:$H,$A12) | E12: =SUMIFS('Delivery Plan'!$G:$G,'Delivery Plan'!$H:$H,$A12,'Delivery Plan'!$I:$I,"Done") | F12: =IFERROR(E12/C12,0)
B13: TOTAL | C13: =SUM(C5:C12) | D13: =SUM(D5:D12) | E13: =SUM(E5:E12) | F13: =IFERROR(E13/C13,0)
A15: Buildable today (R1-R5): | C15: =SUMIFS('Delivery Plan'!$G:$G,'Delivery Plan'!$G:$G,"R1")+SUMIFS('Delivery Plan'!$G:$G,'Delivery Plan'!$G:$G,"R2")+SUMIFS('Delivery Plan'!$G:$G,'Delivery Plan'!$G:$G,"R3")+SUMIFS('Delivery Plan'!$G:$G,'Delivery Plan'!$G:$G,"R4")+SUMIFS('Delivery Plan'!$G:$G,'Delivery Plan'!$G:$G,"R5")
A16: Blocked on your input: | C16: =SUMIFS('Delivery Plan'!$G:$G,'Delivery Plan'!$G:$G,"NEEDS INPUT")
A18: Every run leaves the app working. If we stop after R3 you still have a usable tool, just without version control.

Sheet Needs Your Input
A1: What I cannot do for you
A2: These are real work items, not excuses. Each needs a thing only you or the organisation can supply. Give me the input and the work moves in the same sitting.
A4: What I need from you | B4: Unblocks | C4: Points | D4: Why it cannot be faked
A5: An LLM API key (Gemini Flash is free at this volume) | B5: D5, D6 — the sub-60% matching layer | C5: 11 | D5: Without a provider the third matching layer never runs. Fuzzy alone still works, but the hard lines stay questions for the operator.
A6: Ten real scanned or photographed invoices | B6: F3, F4, F5 — OCR proven end to end | C6: 10 | D6: OCR accuracy depends entirely on your paper: fonts, stamps, skew, scan quality. Any number I quote from synthetic files would be fiction.
A7: Written go-ahead to write into ERPNext UAT | B7: H4, H6, H7 — items actually created | C7: 15 | D7: Writing to a live system is your call, not mine. Dry-run shows the exact payload first.
A8: An ERPNext login per creator | B8: H5, H8 — PROD go-live | C8: 8 | D8: A shared account leaves an audit trail naming nobody. This blocks PROD by design, not by preference.
A9: Which desktop or box hosts it, and can it stay on | B9: J1, F3, J7 — deployment | C9: 9 | D9: Everything else is ready. I need a machine name and admin rights on it.
A10: Your judgement on 889 groups: how far to cut | B10: I1, I3, I4, I5 — the clean-up | C10: 23 | D10: Which groups are genuinely duplicates is a business judgement about your materials. Guessing would corrupt the master.
A11: CA verification of specialised HSN codes | B11: I6 — HSN backfill | C11: 5 | D11: Carried over from the item master work. Wrong HSN is a GST exposure, so it needs a human who is accountable.
A12: Two weeks after go-live, and the creators' time | B12: J4, J5, J6 — training and the watch | C12: 11 | D12: Training needs people in a room. The watch needs time to pass.
B13: TOTAL BLOCKED | C13: =SUM(C5:C12)

Sheet Epics
A1: Epics
A2: Calculated from the Delivery Plan.
A4: Epic | B4: What it covers | C4: Stories | D4: Points | E4: Done pts | F4: Complete %
A5: E0 Brand & Shell | B5: MiniMines palette, logo and typeface; the stats block removed | C5: =COUNTIFS('Delivery Plan'!$C:$C,$A5) | D5: =SUMIFS('Delivery Plan'!$G:$G,'Delivery Plan'!$C:$C,$A5) | E5: =SUMIFS('Delivery Plan'!$G:$G,'Delivery Plan'!$C:$C,$A5,'Delivery Plan'!$I:$I,"Done") | F5: =IFERROR(E5/D5,0)
