Workbook

Sheet Delivery Plan
A1: Item Code Studio — Delivery Plan
A2: Prepared for Anuraag · 6 August 2026 · v2.0 · R1-R5 are today's build runs. S0 = already built and verified. NEEDS INPUT = cannot be done by me; the Notes column says what is required.
A4: ID | B4: Epic | C4: Story | D4: Acceptance criteria | E4: Priority | F4: Points | G4: Run | H4: Status | I4: Depends on | J4: Notes
A5: K1 | B5: E0 Brand & Shell | C5: Apply the MiniMines theme | D5: Palette from m-mines.com (#001b2e navy, #04aed1 teal, #3b6e93 steel), Barlow typeface, minimines-logo.svg in the header. Light and dark both legible. | E5: Must | F5: 5 | G5: R1 | H5: Not started | J5: Reused from ATT_Platform, not reinvented
A6: K2 | B6: E0 Brand & Shell | C6: Remove the stats block | D6: The counts panel in the bottom-left corner is gone. Nothing shifts or leaves a gap. | E6: Must | F6: 1 | G6: R1 | H6: Not started | I6: K1 | J6: Your instruction
A7: A1 | B7: E1 Access & Identity | C7: Split landing page | D7: One page, two halves: Decoder left, Directory right, Log in top-right. No credentials needed to use either half. | E7: Must | F7: 8 | G7: R1 | H7: Not started | I7: K1 | J7: The main page for everyone
A8: A2 | B8: E1 Access & Identity | C8: Decoder half | D8: Paste any code, get head, sub-head, group, every spec with its per-group label, vendor. 00 reads 'not applicable'. Malformed input explains why. | E8: Must | F8: 3 | G8: R1 | H8: Not started | I8: A1
A9: A4 | B9: E1 Access & Identity | C9: Directory half | D9: Search 1,947 items by code, name or description. Row opens a read-only detail card. | E9: Must | F9: 5 | G9: R1 | H9: Not started | I9: A1
A10: A3 | B10: E1 Access & Identity | C10: Dictionary browse | D10: Search 889 groups; open one to see its spec slots and values. Reachable from the directory half. | E10: Must | F10: 3 | G10: R1 | H10: Not started | I10: A4
A11: A8 | B11: E1 Access & Identity | C11: Server-side write protection | D11: Every mutating endpoint returns 401 to an unauthenticated caller invoked directly, not merely hidden in the interface. | E11: Must | F11: 3 | G11: R1 | H11: Not started | J11: The actual boundary
A12: A5 | B12: E1 Access & Identity | C12: Login | D12: Username and password against the user table, scrypt hashed. Bad credentials give one generic message. | E12: Must | F12: 5 | G12: R2 | H12: Not started | I12: A8 | J12: Simple by instruction
A13: A6 | B13: E1 Access & Identity | C13: Session handling | D13: HMAC-signed HttpOnly cookie, 12h expiry, logout clears it. Expiry returns to the landing page, never a blank screen. | E13: Must | F13: 3 | G13: R2 | H13: Not started | I13: A5
A14: A9 | B14: E1 Access & Identity | C14: Attribution from session | D14: created_by comes from the session. The forgeable X-User header is deleted from the codebase. | E14: Must | F14: 2 | G14: R2 | H14: Not started | I14: A6 | J14: Closes a real hole
A15: A7 | B15: E1 Access & Identity | C15: Creator shell | D15: After login: Create, Item master, Activity. The landing page stays reachable while logged in. | E15: Must | F15: 3 | G15: R2 | H15: Not started | I15: A6
A16: A10 | B16: E1 Access & Identity | C16: User management | D16: manage.py adduser / disable / resetpw. At least one active creator must always remain. | E16: Must | F16: 3 | G16: R2 | H16: Not started | I16: A5 | J16: CLI is enough at this size
A17: A11 | B17: E1 Access & Identity | C17: Change own password | D17: A logged-in creator can change their password; the old one is required. | E17: Should | F17: 2 | G17: R2 | H17: Not started | I17: A5
A18: C10 | B18: E3 Code Engine | C18: Create screen with the three phases | D18: Paste or upload, then every line shows what phase 1 found, which group phase 2 chose, and what phase 3 read into each slot. | E18: Must | F18: 5 | G18: R3 | H18: Not started | I18: A7 | J18: Engine exists; this is the gated screen
A19: F8 | B19: E5 Invoice & OCR | C19: Invoice upload wired into Create | D19: Drop a PDF, scan, photo, Excel or CSV and get one row per line item, each resolving independently. | E19: Must | F19: 5 | G19: R3 | H19: Not started | I19: C10 | J19: Engine exists
A20: K3 | B20: E6 Master & Restructure | C20: Conditional cascading dropdowns | D20: Choosing a head filters sub-heads to that head. Choosing a sub-head filters groups to that sub-head only. Choosing a group re-renders its spec slots with that group's labels. | E20: Must | F20: 8 | G20: R3 | H20: Not started | I20: C10 | J20: Core of your edit requirement
A21: K4 | B21: E6 Master & Restructure | C21: Live code recomputation | D21: Any change to head, sub-head, group, spec or vendor recomputes the code immediately, obeying the interior-00 and trailing-truncate rules. | E21: Must | F21: 5 | G21: R3 | H21: Not started | I21: K3
A22: K5 | B22: E6 Master & Restructure | C22: Edit before submit | D22: Every proposed code carries an Edit control. Nothing is written until Submit. | E22: Must | F22: 3 | G22: R3 | H22: Not started | I22: K4
A23: B5 | B23: E2 API v1 | C23: Idempotent commit | D23: A commit carries a client token; replaying it returns the original code instead of issuing a second. | E23: Must | F23: 3 | G23: R3 | H23: Not started | I23: K5 | J23: Guards double-click
A24: C8 | B24: E3 Code Engine | C24: Concurrent issuance safety | D24: Two creators submitting in the same second cannot receive the same code. Proven by a concurrent test, not by argument. | E24: Must | F24: 5 | G24: R3 | H24: Not started | I24: B5
A25: K6 | B25: E6 Master & Restructure | C25: Item master as an editable directory | D25: Same rows and columns as the public directory, every field editable in place, with the same cascading dropdowns. | E25: Must | F25: 8 | G25: R4 | H25: Not started | I25: K3 | J25: Your instruction
A26: K7 | B26: E6 Master & Restructure | C26: Revision history | D26: Every save snapshots the whole row with who, when and what changed. Nothing is overwritten in place. | E26: Must | F26: 8 | G26: R4 | H26: Not started | I26: K6 | J26: The version-control requirement
A27: K8 | B27: E6 Master & Restructure | C27: Revert to a previous version | D27: Any earlier version can be restored in one click. The revert is itself a new version, so it can be undone too. | E27: Must | F27: 5 | G27: R4 | H27: Not started | I27: K7
A28: K9 | B28: E6 Master & Restructure | C28: Activity feed with diffs | D28: Activity shows field-level before and after, filterable by person, item and date, with Revert on each entry. | E28: Must | F28: 5 | G28: R4 | H28: Not started | I28: K7
A29: G3 | B29: E6 Master & Restructure | C29: Move, merge, retire, rename | D29: Each shows a full impact preview listing what re-codes and what stays frozen. | E29: Must | F29: 8 | G29: S0 | H29: Done | J29: Built and tested on group Tissue
A30: K10 | B30: E6 Master & Restructure | C30: Revert respects frozen codes | D30: A revert never rewrites a code that is live in ERPNext. It restores fields and says plainly what it could not restore. | E30: Must | F30: 5 | G30: R4 | H30: Not started | I30: K8 | J30: Where version control meets freeze-on-first-use
A31: G5 | B31: E6 Master & Restructure | C31: Excel export | D31: Item_Master, Item_Code_Master, Code_Mapping and Audit_Trail in one workbook. | E31: Must | F31: 5 | G31: S0 | H31: Done
A32: B1 | B32: E2 API v1 | C32: Version and freeze the contract | D32: Everything served under /api/v1 exactly as the PDR documents it. | E32: Must | F32: 5 | G32: R5 | H32: Not started | I32: A8 | J32: So the larger system can build against it
A33: B2 | B33: E2 API v1 | C33: Uniform error envelope | D33: Every failure returns ok:false with a stable machine code. No stack traces reach the client. | E33: Must | F33: 3 | G33: R5 | H33: Not started | I33: B1
A34: B3 | B34: E2 API v1 | C34: Self-served API docs | D34: GET /api/docs lists every endpoint with request and response examples. | E34: Should | F34: 3 | G34: R5 | H34: Not started | I34: B1
A35: B4 | B35: E2 API v1 | C35: Pagination and filtering | D35: List endpoints take q, limit, offset, status and return total alongside rows. | E35: Should | F35: 2 | G35: R5 | H35: Not started | I35: B1
A36: B6 | B36: E2 API v1 | C36: Public endpoint hardening | D36: Payload caps and a simple per-IP rate limit on public reads. | E36: Should | F36: 2 | G36: R5 | H36: Not started | I36: A8
A37: B7 | B37: E2 API v1 | C37: Smoke suite | D37: A stdlib script exercises every endpoint including auth failures and runs in under a minute. | E37: Must | F37: 5 | G37: R5 | H37: Not started | I37: B2
A38: J7 | B38: E9 Deploy & Handover | C38: Deploy to the internal server | D38: Runs on the nominated machine, reachable by hostname on the LAN, starts on boot, survives a restart. | E38: Must | F38: 5 | G38: R5 | H38: Not started | I38: B7 | J38: Internal grade, not production grade
A39: J2 | B39: E9 Deploy & Handover | C39: Automated backup | D39: Daily copy of itemcode.db plus a weekly Excel export, both written off the host machine. | E39: Must | F39: 3 | G39: R5 | H39: Not started | I39: J7
A40: J8 | B40: E9 Deploy & Handover | C40: Seed and go-live check | D40: Fresh seed from the source workbooks on the server; counts match; a code is issued end to end. | E40: Must | F40: 3 | G40: R5 | H40: Not started | I40: J7
A41: C1 | B41: E3 Code Engine | C41: Code grammar assembly | D41: Interior gap 00, trailing gaps dropped, vendor forces 17. Only 7/9/11/13/15/17 accepted. | E41: Must | F41: 8 | G41: S0 | H41: Done | J41: Verified against RMBS0010206100007
...

Sheet Runs
A1: Build runs — one sitting, today
A2: Points roll up from the Delivery Plan. Each run ends with something you can open and use.
A4: Run | B4: What it delivers | C4: Points | D4: Stories | E4: Done | F4: Complete %
A5: S0 | B5: Already built: the grammar, all three phases, matching, invoice extraction, the master, restructuring, export, ERP read | C5: =SUMIFS('Delivery Plan'!$F:$F,'Delivery Plan'!$G:$G,$A5) | D5: =COUNTIFS('Delivery Plan'!$G:$G,$A5) | E5: =SUMIFS('Delivery Plan'!$F:$F,'Delivery Plan'!$G:$G,$A5,'Delivery Plan'!$H:$H,"Done") | F5: =IFERROR(E5/C5,0)
A6: R1 | B6: MiniMines theme and logo, the split landing page — decoder one side, directory the other, log in on top. Stats block removed | C6: =SUMIFS('Delivery Plan'!$F:$F,'Delivery Plan'!$G:$G,$A6) | D6: =COUNTIFS('Delivery Plan'!$G:$G,$A6) | E6: =SUMIFS('Delivery Plan'!$F:$F,'Delivery Plan'!$G:$G,$A6,'Delivery Plan'!$H:$H,"Done") | F6: =IFERROR(E6/C6,0)
A7: R2 | B7: Login, sessions, attribution from the session, user management, the creator shell behind the gate | C7: =SUMIFS('Delivery Plan'!$F:$F,'Delivery Plan'!$G:$G,$A7) | D7: =COUNTIFS('Delivery Plan'!$G:$G,$A7) | E7: =SUMIFS('Delivery Plan'!$F:$F,'Delivery Plan'!$G:$G,$A7,'Delivery Plan'!$H:$H,"Done") | F7: =IFERROR(E7/C7,0)
A8: R3 | B8: The create screen: paste or upload an invoice, three phases shown per line, cascading head-sub-head-group dropdowns, live code recomputation, edit before submit | C8: =SUMIFS('Delivery Plan'!$F:$F,'Delivery Plan'!$G:$G,$A8) | D8: =COUNTIFS('Delivery Plan'!$G:$G,$A8) | E8: =SUMIFS('Delivery Plan'!$F:$F,'Delivery Plan'!$G:$G,$A8,'Delivery Plan'!$H:$H,"Done") | F8: =IFERROR(E8/C8,0)
A9: R4 | B9: Item master as a fully editable directory, revision history on every save, one-click revert, activity feed with field-level diffs | C9: =SUMIFS('Delivery Plan'!$F:$F,'Delivery Plan'!$G:$G,$A9) | D9: =COUNTIFS('Delivery Plan'!$G:$G,$A9) | E9: =SUMIFS('Delivery Plan'!$F:$F,'Delivery Plan'!$G:$G,$A9,'Delivery Plan'!$H:$H,"Done") | F9: =IFERROR(E9/C9,0)
A10: R5 | B10: API frozen at /api/v1 with a real error contract, smoke suite, deployed to the internal server, starts on boot, daily backup | C10: =SUMIFS('Delivery Plan'!$F:$F,'Delivery Plan'!$G:$G,$A10) | D10: =COUNTIFS('Delivery Plan'!$G:$G,$A10) | E10: =SUMIFS('Delivery Plan'!$F:$F,'Delivery Plan'!$G:$G,$A10,'Delivery Plan'!$H:$H,"Done") | F10: =IFERROR(E10/C10,0)
A11: NEEDS INPUT | B11: Blocked on something only you or the organisation can supply — see the next tab | C11: =SUMIFS('Delivery Plan'!$F:$F,'Delivery Plan'!$G:$G,$A11) | D11: =COUNTIFS('Delivery Plan'!$G:$G,$A11) | E11: =SUMIFS('Delivery Plan'!$F:$F,'Delivery Plan'!$G:$G,$A11,'Delivery Plan'!$H:$H,"Done") | F11: =IFERROR(E11/C11,0)
A12: BACKLOG | B12: Agreed but not needed for go-live | C12: =SUMIFS('Delivery Plan'!$F:$F,'Delivery Plan'!$G:$G,$A12) | D12: =COUNTIFS('Delivery Plan'!$G:$G,$A12) | E12: =SUMIFS('Delivery Plan'!$F:$F,'Delivery Plan'!$G:$G,$A12,'Delivery Plan'!$H:$H,"Done") | F12: =IFERROR(E12/C12,0)
B13: TOTAL | C13: =SUM(C5:C12) | D13: =SUM(D5:D12) | E13: =SUM(E5:E12) | F13: =IFERROR(E13/C13,0)
A15: Buildable today (R1-R5): | C15: =SUMIFS('Delivery Plan'!$F:$F,'Delivery Plan'!$G:$G,"R1")+SUMIFS('Delivery Plan'!$F:$F,'Delivery Plan'!$G:$G,"R2")+SUMIFS('Delivery Plan'!$F:$F,'Delivery Plan'!$G:$G,"R3")+SUMIFS('Delivery Plan'!$F:$F,'Delivery Plan'!$G:$G,"R4")+SUMIFS('Delivery Plan'!$F:$F,'Delivery Plan'!$G:$G,"R5")
A16: Blocked on your input: | C16: =SUMIFS('Delivery Plan'!$F:$F,'Delivery Plan'!$G:$G,"NEEDS INPUT")
A18: Every run leaves the app working. If we stop after R3 you still have a usable tool, just without version control.

Sheet Needs Your Input
A1: What I cannot do for you
A2: These are real work items, not excuses. Each needs a thing only you or the organisation can supply. Give me the input and the work moves in the same sitting.
A4: What I need from you | B4: Unblocks | C4: Points | D4: Why it cannot be faked
A5: An LLM API key (Gemini Flash is free at this volume) | B5: D5, D6 — the sub-60% matching layer | C5: 11 | D5: Without a provider the third matching layer never runs. Fuzzy alone still works, but the hard lines stay questions for the operator.
A6: Ten real scanned or photographed invoices | B6: F3, F4, F5 — OCR proven end to end | C6: 10 | D6: OCR accuracy depends entirely on your paper: fonts, stamps, skew, scan quality. Any number I quote from synthetic files would be fiction.
A7: Written go-ahead to write into ERPNext UAT | B7: H4, H6, H7 — items actually created | C7: 15 | D7: Writing to a live system is your call, not mine. Dry-run shows the exact payload first.
A8: An ERPNext login per creator | B8: H5, H8 — PROD go-live | C8: 8 | D8: A shared account leaves an audit trail naming nobody. This blocks PROD by design, not by preference.
A9: Which desktop or box hosts it, and can it stay on | B9: J1, F3, J7 — deployment | C9: 9 | D9: Everything else is ready. I need a machine name and admin rights on it.
A10: Your judgement on 889 groups: how far to cut | B10: I1, I3, I4, I5 — the clean-up | C10: 23 | D10: Which groups are genuinely duplicates is a business judgement about your materials. Guessing would corrupt the master.
A11: CA verification of specialised HSN codes | B11: I6 — HSN backfill | C11: 5 | D11: Carried over from the item master work. Wrong HSN is a GST exposure, so it needs a human who is accountable.
A12: Two weeks after go-live, and the creators' time | B12: J4, J5, J6 — training and the watch | C12: 11 | D12: Training needs people in a room. The watch needs time to pass.
B13: TOTAL BLOCKED | C13: =SUM(C5:C12)

Sheet Epics
A1: Epics
A2: Calculated from the Delivery Plan.
A4: Epic | B4: What it covers | C4: Stories | D4: Points | E4: Done pts | F4: Complete %
A5: E0 Brand & Shell | B5: MiniMines palette, logo and typeface; the stats block removed | C5: =COUNTIFS('Delivery Plan'!$B:$B,$A5) | D5: =SUMIFS('Delivery Plan'!$F:$F,'Delivery Plan'!$B:$B,$A5) | E5: =SUMIFS('Delivery Plan'!$F:$F,'Delivery Plan'!$B:$B,$A5,'Delivery Plan'!$H:$H,"Done") | F5: =IFERROR(E5/D5,0)
A6: E1 Access & Identity | B6: The split landing page anyone can use, and a login that leads to creation | C6: =COUNTIFS('Delivery Plan'!$B:$B,$A6) | D6: =SUMIFS('Delivery Plan'!$F:$F,'Delivery Plan'!$B:$B,$A6) | E6: =SUMIFS('Delivery Plan'!$F:$F,'Delivery Plan'!$B:$B,$A6,'Delivery Plan'!$H:$H,"Done") | F6: =IFERROR(E6/D6,0)
A7: E2 API v1 | B7: A stable, documented, versioned contract for the larger system | C7: =COUNTIFS('Delivery Plan'!$B:$B,$A7) | D7: =SUMIFS('Delivery Plan'!$F:$F,'Delivery Plan'!$B:$B,$A7) | E7: =SUMIFS('Delivery Plan'!$F:$F,'Delivery Plan'!$B:$B,$A7,'Delivery Plan'!$H:$H,"Done") | F7: =IFERROR(E7/D7,0)
A8: E3 Code Engine | B8: The grammar, three phases, numbering, vacancies, freeze-on-first-use | C8: =COUNTIFS('Delivery Plan'!$B:$B,$A8) | D8: =SUMIFS('Delivery Plan'!$F:$F,'Delivery Plan'!$B:$B,$A8) | E8: =SUMIFS('Delivery Plan'!$F:$F,'Delivery Plan'!$B:$B,$A8,'Delivery Plan'!$H:$H,"Done") | F8: =IFERROR(E8/D8,0)
A9: E4 Matching & LLM | B9: Normaliser, fuzzy blend, alias learning, LLM below 60% confidence | C9: =COUNTIFS('Delivery Plan'!$B:$B,$A9) | D9: =SUMIFS('Delivery Plan'!$F:$F,'Delivery Plan'!$B:$B,$A9) | E9: =SUMIFS('Delivery Plan'!$F:$F,'Delivery Plan'!$B:$B,$A9,'Delivery Plan'!$H:$H,"Done") | F9: =IFERROR(E9/D9,0)
A10: E5 Invoice & OCR | B10: Reading text, PDF, scanned and photographed invoices into resolvable lines | C10: =COUNTIFS('Delivery Plan'!$B:$B,$A10) | D10: =SUMIFS('Delivery Plan'!$F:$F,'Delivery Plan'!$B:$B,$A10) | E10: =SUMIFS('Delivery Plan'!$F:$F,'Delivery Plan'!$B:$B,$A10,'Delivery Plan'!$H:$H,"Done") | F10: =IFERROR(E10/D10,0)
A11: E6 Master & Restructure | B11: Editable master, cascading dropdowns, revision history, revert, restructuring | C11: =COUNTIFS('Delivery Plan'!$B:$B,$A11) | D11: =SUMIFS('Delivery Plan'!$F:$F,'Delivery Plan'!$B:$B,$A11) | E11: =SUMIFS('Delivery Plan'!$F:$F,'Delivery Plan'!$B:$B,$A11,'Delivery Plan'!$H:$H,"Done") | F11: =IFERROR(E11/D11,0)
A12: E7 ERPNext | B12: Reading live truth, and writing items back on submit | C12: =COUNTIFS('Delivery Plan'!$B:$B,$A12) | D12: =SUMIFS('Delivery Plan'!$F:$F,'Delivery Plan'!$B:$B,$A12) | E12: =SUMIFS('Delivery Plan'!$F:$F,'Delivery Plan'!$B:$B,$A12,'Delivery Plan'!$H:$H,"Done") | F12: =IFERROR(E12/D12,0)
A13: E8 Data Quality | B13: Duplicate groups, junk codes, missing HSN | C13: =COUNTIFS('Delivery Plan'!$B:$B,$A13) | D13: =SUMIFS('Delivery Plan'!$F:$F,'Delivery Plan'!$B:$B,$A13) | E13: =SUMIFS('Delivery Plan'!$F:$F,'Delivery Plan'!$B:$B,$A13,'Delivery Plan'!$H:$H,"Done") | F13: =IFERROR(E13/D13,0)
A14: E9 Deploy & Handover | B14: Server, backup, start-on-boot, training, runbook, post-launch watch | C14: =COUNTIFS('Delivery Plan'!$B:$B,$A14) | D14: =SUMIFS('Delivery Plan'!$F:$F,'Delivery Plan'!$B:$B,$A14) | E14: =SUMIFS('Delivery Plan'!$F:$F,'Delivery Plan'!$B:$B,$A14,'Delivery Plan'!$H:$H,"Done") | F14: =IFERROR(E14/D14,0)
B15: TOTAL | C15: =SUM(C5:C14) | D15: =SUM(D5:D14) | E15: =SUM(E5:E14) | F15: =IFERROR(E15/D15,0)

Sheet Risks
A1: Risks
A3: # | B3: Risk | C3: Impact | D3: Likelihood | E3: Response | F3: Status
A4: 1 | B4: Building all five runs in one sitting means less testing per feature than the six-sprint plan allowed. | C4: High | D4: Certain | E4: Each run ends working and is exercised against the real seeded data before the next starts. Where a run is thin, it is named in the handover rather than hidden. | F4: Accepted
A5: 2 | B5: Version control plus freeze-on-first-use interact awkwardly: a revert cannot restore a code that ERPNext has frozen. | C5: High | D5: Likely | E5: K10 makes revert restore fields only, and say plainly what it could not restore. Never a silent partial revert. | F5: Open
A6: 3 | B6: OCR accuracy is completely unmeasured on your paper. | C6: High | D6: Possible | E6: Blocked on ten real invoices. Until then OCR is present but unproven, and the handover says so. | F6: Blocked
A7: 4 | B7: The host is a single point of failure. If it sleeps, nobody can issue a code. | C7: High | D7: Likely | E7: Daily off-machine backup, start-on-boot. Move to an always-on box if it bites. | F7: Open
A8: 5 | B8: Passwords cross the LAN in the clear over plain HTTP. | C8: Medium | D8: Certain | E8: Accepted for an internal tool. Use passwords not reused elsewhere. TLS if it ever leaves the LAN. | F8: Accepted
A9: 6 | B9: Group de-duplication keeps slipping. Every month more codes freeze and the clean-up gets permanently dearer. | C9: High | D9: Likely | E9: Blocked on your judgement. This is the item I would push hardest to unblock first. | F9: Blocked
A10: 7 | B10: Writing to PROD under a shared account leaves an audit trail naming nobody. | C10: High | D10: Certain | E10: Per-creator ERP credentials block PROD go-live by design. | F10: Blocked
A11: 8 | B11: Anyone who can log in can restructure the master, with no approval gate, by instruction. | C11: Medium | D11: Possible | E11: Preview, attribution, full revision history and one-click revert. Revisit only if it actually causes harm. | F11: Accepted
A12: 9 | B12: A structural change re-codes an item ERPNext has already transacted. | C12: High | D12: Unlikely | E12: Freeze-on-first-use makes it impossible by design; every change is previewed first. | F12: Mitigated
A13: 10 | B13: The larger system builds against an API that then shifts underneath it. | C13: Medium | D13: Possible | E13: R5 freezes the contract at /api/v1 before anyone integrates. | F13: Open

Sheet Decisions
A1: Decision log
A2: Amber rows need your word before or during the build.
A4: # | B4: Decision | C4: Rationale | D4: Status
A5: 1 | B5: Variable-length codes, never padded | C5: Interior gaps carry meaning as 00; trailing gaps carry none. Lengths 7/9/11/13/15/17. | D5: Locked
A6: 2 | B6: Vendor sits last, only in groups that declare it | C6: Four battery groups declare a Maker slot. Elsewhere one item keeps one code regardless of supplier. | D6: Locked
A7: 3 | B7: Vendor from the invoice line only, never the header | C7: A supplier named at the top of a page says nothing about an individual line. | D7: Locked
A8: 4 | B8: No -R / -W / -F state suffixes | C8: Removed entirely. | D8: Locked
A9: 5 | B9: Spec slot meaning is per group | C9: Air Freshener uses Type and Size; Battery Pack uses Form Factor, Chemistry, Size, Capacity, Maker. | D9: Locked
A10: 6 | B10: Group numbers restart inside each sub-head | C10: 999 per sub-head is ample at 889 groups. | D10: Locked
A11: 7 | B11: A vacated group number is parked, not reused | C11: Released only to a >=88% name match. The number carries the meaning of what held it. | D11: Locked
A12: 8 | B12: Prefix collisions walk to the next free combination | C12: Seeded prefixes read from codes already issued, so CEEU and its like survive. | D12: Locked
A13: 9 | B13: No approval workflow | C13: Preview, attribution, revision history and revert replace permission. | D13: Locked
A14: 10 | B14: Two tiers, not roles: public read, login to create | C14: You have two kinds of people and one permission. A role matrix would never earn its keep. | D14: Locked
A15: 11 | B15: Landing page is split: decoder one side, directory the other | C15: Most people only ever need to look something up. That is the front door. | D15: Locked
A16: 12 | B16: Item master is the editable twin of the public directory | C16: Same rows, same columns, editable behind the login. | D16: Locked
... A22: 18 | B22: One SQLite file on one internal server | C22: Makes duplicate codes structurally impossible. Accepts the host as a single point of failure. | D22: Locked

Sheet Definition of Done
A1: Definition of Done
A2: Compressed to one sitting, so this is the floor, not the ceiling.
A4: 1 | B4: The acceptance criteria on the Delivery Plan row are met as written, not as reinterpreted.
A5: 2 | B5: Exercised against the real seeded data — 889 groups, 1,947 items, 2,677 live ERP codes — never a toy fixture.
A6: 3 | B6: Any rule that protects the master is enforced in the API, not only in the interface.
A7: 4 | B7: One failure path tried on purpose, producing a clear message rather than a crash or a silent wrong answer.
A8: 5 | B8: Every write is attributed to the authenticated user and appears in the activity log.
A9: 6 | B9: The app still starts and the previous runs still work.
A10: 7 | B10: Anything thin or untested is written into the handover, not carried in someone's head.
